<robot
  name="mvpcrane">
  <link
    name="base_link">
    <inertial>
      <origin
        xyz="0.0507117835790473 1.47451495458029E-17 0.0268762105129842"
        rpy="0 0 0" />
      <mass
        value="1.90627005747125" />
      <inertia
        ixx="0.0153580852373972"
        ixy="-3.86425952329233E-18"
        ixz="-0.00275171992820305"
        iyy="0.0151689877403363"
        iyz="-1.96014604987705E-18"
        izz="0.0241891871044715" />
    </inertial>
    <visual>
      <origin
        xyz="0 0 0"
        rpy="0 0 0" />
      <geometry>
        <mesh
          filename="package://me212base/model/meshes/visual/mvpcrane/base_link.stl" />
      </geometry>
      <material
        name="">
        <color
          rgba="0.792156862745098 0.819607843137255 0.933333333333333 1" />
      </material>
    </visual>
    <collision>
      <origin
        xyz="0 0 0"
        rpy="0 0 0" />
      <geometry>
        <mesh
          filename="package://me212base/model/meshes/visual/mvpcrane/base_link.stl" />
      </geometry>
    </collision>
  </link>
  <link
    name="rwheel_link">
    <inertial>
      <origin
        xyz="5.55111512312578E-17 0 0"
        rpy="0 0 0" />
      <mass
        value="0.0829576810088555" />
      <inertia
        ixx="2.62267251939455E-05"
        ixy="-4.10376130191917E-38"
        ixz="0"
        iyy="4.38120252828018E-05"
        iyz="-6.51271857308242E-38"
        izz="2.62267251939454E-05" />
    </inertial>
    <visual>
      <origin
        xyz="0 0 0"
        rpy="0 0 0" />
      <geometry>
        <mesh
          filename="package://me212base/model/meshes/visual/mvpcrane/rwheel_link.stl" />
      </geometry>
      <material
        name="">
        <color
          rgba="0.792156862745098 0.819607843137255 0.933333333333333 1" />
      </material>
    </visual>
    <collision>
      <origin
        xyz="0 0 0"
        rpy="0 0 0" />
      <geometry>
        <mesh
          filename="package://me212base/model/meshes/visual/mvpcrane/rwheel_link.stl" />
      </geometry>
    </collision>
  </link>
  <joint
    name="rwheel_joint"
    type="continuous">
    <origin
      xyz="0.08 -0.1135 -0.0545"
      rpy="0 0 3.70074341541719E-16" />
    <parent
      link="base_link" />
    <child
      link="rwheel_link" />
    <axis
      xyz="0 1 0" />
  </joint>
  <link
    name="lwheel_link">
    <inertial>
      <origin
        xyz="0 0 0"
        rpy="0 0 0" />
      <mass
        value="0.0829576810088555" />
      <inertia
        ixx="2.62267251939455E-05"
        ixy="-7.07229507600784E-22"
        ixz="2.11758236813575E-22"
        iyy="4.38120252828018E-05"
        iyz="-3.48215852980651E-24"
        izz="2.62267251939455E-05" />
    </inertial>
    <visual>
      <origin
        xyz="0 0 0"
        rpy="0 0 0" />
      <geometry>
        <mesh
          filename="package://me212base/model/meshes/visual/mvpcrane/lwheel_link.stl" />
      </geometry>
      <material
        name="">
        <color
          rgba="0.792156862745098 0.819607843137255 0.933333333333333 1" />
      </material>
    </visual>
    <collision>
      <origin
        xyz="0 0 0"
        rpy="0 0 0" />
      <geometry>
        <mesh
          filename="package://me212base/model/meshes/visual/mvpcrane/lwheel_link.stl" />
      </geometry>
    </collision>
  </link>
  <joint
    name="lwheel_joint"
    type="continuous">
    <origin
      xyz="0.0799999999999998 0.1135 -0.0545"
      rpy="0 0.0673424314711914 3.70074341541719E-16" />
    <parent
      link="base_link" />
    <child
      link="lwheel_link" />
    <axis
      xyz="0 1 0" />
  </joint>
  <link
    name="bwheel_mount_link">
    <inertial>
      <origin
        xyz="0 -3.46944695195361E-18 -0.0226324626865672"
        rpy="0 0 0" />
      <mass
        value="0.0268" />
      <inertia
        ixx="1.31085964241293E-05"
        ixy="8.13934053179257E-22"
        ixz="-8.55422040183102E-22"
        iyy="1.14710964241293E-05"
        iyz="-1.42903905292742E-22"
        izz="8.78416666666666E-06" />
    </inertial>
    <visual>
      <origin
        xyz="0 0 0"
        rpy="0 0 0" />
      <geometry>
        <mesh
          filename="package://me212base/model/meshes/visual/mvpcrane/bwheel_mount_link.stl" />
      </geometry>
      <material
        name="">
        <color
          rgba="0.792156862745098 0.819607843137255 0.933333333333333 1" />
      </material>
    </visual>
    <collision>
      <origin
        xyz="0 0 0"
        rpy="0 0 0" />
      <geometry>
        <mesh
          filename="package://me212base/model/meshes/visual/mvpcrane/bwheel_mount_link.stl" />
      </geometry>
    </collision>
  </link>
  <joint
    name="bwheel_mount_joint"
    type="continuous">
    <origin
      xyz="-0.1 0 -0.00499999999999979"
      rpy="-1.38777878078144E-15 9.86076131526265E-32 3.97829917157348E-16" />
    <parent
      link="base_link" />
    <child
      link="bwheel_mount_link" />
    <axis
      xyz="0 0 1" />
  </joint>
  <link
    name="bwheel_link">
    <inertial>
      <origin
        xyz="0 4.33680868994202E-18 0"
        rpy="0 0 0" />
      <mass
        value="0.0663661448070844" />
      <inertia
        ixx="1.97370149400235E-05"
        ixy="-1.47362444040855E-22"
        ixz="1.31655367292096E-36"
        iyy="3.50496202262414E-05"
        iyz="7.91235252580677E-37"
        izz="1.97370149400235E-05" />
    </inertial>
    <visual>
      <origin
        xyz="0 0 0"
        rpy="0 0 0" />
      <geometry>
        <mesh
          filename="package://me212base/model/meshes/visual/mvpcrane/bwheel_link.stl" />
      </geometry>
      <material
        name="">
        <color
          rgba="0.792156862745098 0.819607843137255 0.933333333333333 1" />
      </material>
    </visual>
    <collision>
      <origin
        xyz="0 0 0"
        rpy="0 0 0" />
      <geometry>
        <mesh
          filename="package://me212base/model/meshes/visual/mvpcrane/bwheel_link.stl" />
      </geometry>
    </collision>
  </link>
  <joint
    name="bwheel_joint"
    type="continuous">
    <origin
      xyz="0 0 -0.0495"
      rpy="1.38777878078144E-15 1.38777878078123E-17 1.47104550762833E-15" />
    <parent
      link="bwheel_mount_link" />
    <child
      link="bwheel_link" />
    <axis
      xyz="0 1 0" />
  </joint>
</robot>